<?xml version="1.0"?>
<sdf version="1.6">
  <model name="diff_drive_robot">
    <pose>0 0 0.1 0 0 0</pose>
    <link name="base_link">
      <inertial>
        <mass>5.0</mass>
        <inertia>
          <ixx>0.04</ixx>
          <ixy>0.0</ixy>
          <ixz>0.0</ixz>
          <iyy>0.1</iyy>
          <iyz>0.0</iyz>
          <izz>0.04</izz>
        </inertia>
      </inertial>
      <collision name="collision">
        <geometry>
          <box><size>0.6 0.4 0.2</size></box>
        </geometry>
      </collision>
      <visual name="visual">
        <geometry>
          <box><size>0.6 0.4 0.2</size></box>
        </geometry>
        <material>
          <ambient>0.0 0.0 1.0 1.0</ambient>
          <diffuse>0.0 0.0 1.0 1.0</diffuse>
        </material>
      </visual>
    </link>

    <link name="left_wheel_link">
      <pose>0.2 0.22 -0.05 0 1.5707 1.5707</pose> <!-- X Y Z R P Y -->
      <inertial><mass>1</mass></inertial>
      <collision name="collision">
        <geometry><cylinder><radius>0.1</radius><length>0.05</length></cylinder></geometry>
      </collision>
      <visual name="visual">
        <geometry><cylinder><radius>0.1</radius><length>0.05</length></cylinder></geometry>
        <material><ambient>0.2 0.2 0.2 1</ambient><diffuse>0.2 0.2 0.2 1</diffuse></material>
      </visual>
    </link>

    <link name="right_wheel_link">
      <pose>0.2 -0.22 -0.05 0 1.5707 1.5707</pose> <!-- X Y Z R P Y -->
      <inertial><mass>1</mass></inertial>
      <collision name="collision">
        <geometry><cylinder><radius>0.1</radius><length>0.05</length></cylinder></geometry>
      </collision>
      <visual name="visual">
        <geometry><cylinder><radius>0.1</radius><length>0.05</length></cylinder></geometry>
        <material><ambient>0.2 0.2 0.2 1</ambient><diffuse>0.2 0.2 0.2 1</diffuse></material>
      </visual>
    </link>

    <joint name="left_wheel_joint" type="revolute">
      <parent>base_link</parent>
      <child>left_wheel_link</child>
      <axis><xyz>0 0 1</xyz></axis>
    </joint>

    <joint name="right_wheel_joint" type="revolute">
      <parent>base_link</parent>
      <child>right_wheel_link</child>
      <axis><xyz>0 0 1</xyz></axis>
    </joint>

    <!-- Gazebo ROS Diff Drive Plugin -->
    <plugin name="gazebo_ros_diff_drive" filename="libgazebo_ros_diff_drive.so">
      <ros>
        <!-- <namespace>/demo</namespace> -->
      </ros>

      <!-- Update rate in Hz -->
      <update_rate>30</update_rate>

      <!-- wheels -->
      <left_joint>left_wheel_joint</left_joint>
      <right_joint>right_wheel_joint</right_joint>

      <!-- kinematics -->
      <wheel_separation>0.44</wheel_separation> <!-- Distance between center of wheels -->
      <wheel_diameter>0.2</wheel_diameter> <!-- Diameter of the wheels -->

      <!-- limits -->
      <max_wheel_torque>20</max_wheel_torque>
      <max_wheel_acceleration>1.0</max_wheel_acceleration>

      <!-- output -->
      <publish_odom>true</publish_odom>
      <publish_odom_tf>true</publish_odom_tf>
      <publish_wheel_tf>false</publish_wheel_tf> <!-- Usually handled by robot_state_publisher -->

      <odometry_frame>odom</odometry_frame>
      <robot_base_frame>base_link</robot_base_frame>

      <!-- Topic names -->
      <command_topic>cmd_vel</command_topic>
      <odometry_topic>odom</odometry_topic>

    </plugin>
  </model>
</sdf>